<mujoco model="z1">
  <compiler angle="radian" autolimits="true"/>

  <option integrator="implicitfast"/>

  <asset>
    <mesh name="z1_Link00" content_type="model/stl" file="meshes/z1_Link00.STL"/>
    <mesh name="z1_Link01" content_type="model/stl" file="meshes/z1_Link01.STL"/>
    <mesh name="z1_Link02" content_type="model/stl" file="meshes/z1_Link02.STL"/>
    <mesh name="z1_Link03" content_type="model/stl" file="meshes/z1_Link03.STL"/>
    <mesh name="z1_Link04" content_type="model/stl" file="meshes/z1_Link04.STL"/>
    <mesh name="z1_Link05" content_type="model/stl" file="meshes/z1_Link05.STL"/>
    <mesh name="z1_Link06" content_type="model/stl" file="meshes/z1_Link06.STL"/>
    <mesh name="z1_GripperStator" content_type="model/stl" file="meshes/z1_GripperStator.STL"/>
    <mesh name="z1_GripperMover" content_type="model/stl" file="meshes/z1_GripperMover.STL"/>
  </asset>

  <worldbody>
    <geom pos="0 0 -0.0001" quat="1 0 0 0" type="mesh" rgba="0.3 0.3 0.3 1" name="z1_Link00" mesh="z1_Link00"/>
    <body name="link01" pos="0 0 0.0585">
      <inertial pos="2.47e-06 -0.00025198 0.0231717" quat="0.708578 0.705633 0.000281462 -0.000355927" mass="0.673326" diaginertia="0.00128328 0.000839362 0.000719308"/>
      <joint name="joint1" pos="0 0 0" axis="0 0 1" range="-2.61799 2.61799" actuatorfrcrange="-30 30" damping="1" frictionloss="1"/>
      <geom type="mesh" rgba="0.3 0.3 0.3 1" name="z1_Link01" mesh="z1_Link01"/>
      <body name="link02" pos="0 0 0.045">
        <inertial pos="-0.110126 0.00240029 0.00158266" quat="0.00748058 0.707092 -0.0114473 0.70699" mass="1.19132" diaginertia="0.0246612 0.0243113 0.00100468"/>
        <joint name="joint2" pos="0 0 0" axis="0 1 0" range="0 2.96706" actuatorfrcrange="-60 60" damping="2" frictionloss="2"/>
        <geom type="mesh" rgba="0.3 0.3 0.3 1" name="z1_Link02" mesh="z1_Link02"/>
        <body name="link03" pos="-0.35 0 0">
          <inertial pos="0.106092 -0.00541815 0.0347638" quat="0.540557 0.443575 0.426319 0.573839" mass="0.839409" diaginertia="0.00954365 0.00938711 0.000558432"/>
          <joint name="joint3" pos="0 0 0" axis="0 1 0" range="-2.87979 0" actuatorfrcrange="-30 30" damping="1" frictionloss="1"/>
          <geom type="mesh" rgba="0.3 0.3 0.3 1" name="z1_Link03" mesh="z1_Link03"/>
          <body name="link04" pos="0.218 0 0.057">
            <inertial pos="0.0436668 0.00364738 -0.00170192" quat="0.0390835 0.726445 -0.0526787 0.684087" mass="0.564046" diaginertia="0.000981656 0.00094053 0.000302655"/>
            <joint name="joint4" pos="0 0 0" axis="0 1 0" range="-1.51844 1.51844" actuatorfrcrange="-30 30" damping="1" frictionloss="1"/>
            <geom type="mesh" rgba="0.3 0.3 0.3 1" name="z1_Link04" mesh="z1_Link04"/>
            <body name="link05" pos="0.07 0 0">
              <inertial pos="0.0312153 0 0.00646316" quat="0.462205 0.535209 0.53785 0.45895" mass="0.389385" diaginertia="0.000558961 0.000547317 0.000167332"/>
              <joint name="joint5" pos="0 0 0" axis="0 0 1" range="-1.3439 1.3439" actuatorfrcrange="-30 30" damping="1" frictionloss="1"/>
              <geom type="mesh" rgba="0.3 0.3 0.3 1" name="z1_Link05" mesh="z1_Link05"/>
              <body name="link06" pos="0.0492 0 0">
                <inertial pos="0.0413016 0.0312517 0.00710868" quat="0.646697 0.462142 -0.59325 0.127523" mass="0.814795" diaginertia="0.00143745 0.00122156 0.000766159"/>
                <joint name="joint6" pos="0 0 0" axis="1 0 0" range="-2.79253 2.79253" actuatorfrcrange="-30 30" damping="1" frictionloss="1"/>
                <geom type="mesh" rgba="0.3 0.3 0.3 1" name="z1_Link06" mesh="z1_Link06"/>
                <geom pos="0.051 0 0" quat="1 0 0 0" type="mesh" rgba="0.3 0.3 0.3 1" name="z1_GripperStator" mesh="z1_GripperStator"/>
                <body name="gripperMover" pos="0.1 0 0">
                  <inertial pos="0.0132063 0.00476708 0.00380534" quat="0.0631093 0.669067 -0.0615783 0.737953" mass="0.276213" diaginertia="0.000359044 0.000270888 0.000172378"/>
                  <joint name="jointGripper" pos="0 0 0" axis="0 1 0" range="-1.5708 0" actuatorfrcrange="-30 30" damping="1" frictionloss="1"/>
                  <geom type="mesh" rgba="0.3 0.3 0.3 1" name="z1_GripperMover" mesh="z1_GripperMover"/>
                </body>
              </body>
            </body>
          </body>
        </body>
      </body>
    </body>
  </worldbody>
    <contact>
        <exclude body1="link01" body2="link02"/>
        <exclude body1="link02" body2="link03"/>
        <exclude body1="link03" body2="link04"/>
        <exclude body1="link04" body2="link05"/>
        <exclude body1="link05" body2="link06"/>
        <exclude body1="link06" body2="gripperMover"/>
    </contact>
    <actuator>
        <position name="pos_j1" joint="joint1" kp="500" ctrlrange="-2.6 2.6"/>
        <position name="pos_j2" joint="joint2" kp="500" ctrlrange="0.0 2.9"/>
        <position name="pos_j3" joint="joint3" kp="500" ctrlrange="-2.8 0.0"/>
        <position name="pos_j4" joint="joint4" kp="500" ctrlrange="-1.5 1.5"/>
        <position name="pos_j5" joint="joint5" kp="500" ctrlrange="-1.3 1.3"/>
        <position name="pos_j6" joint="joint6" kp="500" ctrlrange="-2.7 2.7"/>
        <position name="pos_gripper" joint="jointGripper" kp="100" ctrlrange="-1.5 0.0"/>
    </actuator>
</mujoco>
